<?xml version='1.0' encoding='UTF-8'?>
<robot name="hand">
  <link name="hand_base">
    <inertial>
      <origin xyz="0.0 0.0 0.0" rpy="0.0 -0.0 0.0"/>
      <mass value="1.0"/>
      <inertia ixx="0.0" ixy="0.0" ixz="0.0" iyy="0.0" iyz="0.0" izz="0.0"/>
    </inertial>
  </link>
  <link name="f1_base_link">
    <inertial>
      <origin xyz="0.0 0.0 0.0" rpy="0.0 -0.0 0.0"/>
      <mass value="0.1"/>
      <inertia ixx="0.0" ixy="0.0" ixz="0.0" iyy="0.0" iyz="0.0" izz="0.0"/>
    </inertial>
  </link>
  <link name="f1_proximal_link">
    <inertial>
      <origin xyz="0.0 0.0 0.0" rpy="0.0 -0.0 0.0"/>
      <mass value="0.0"/>
      <inertia ixx="0.0" ixy="0.0" ixz="0.0" iyy="0.0" iyz="0.0" izz="0.0"/>
    </inertial>
  </link>
  <link name="f1_knuckle_link">
    <inertial>
      <origin xyz="0.0 0.0 0.0" rpy="0.0 -0.0 0.0"/>
      <mass value="0.1"/>
      <inertia ixx="0.0" ixy="0.0" ixz="0.0" iyy="0.0" iyz="0.0" izz="0.0"/>
    </inertial>
    <visual>
      <geometry>
        <mesh filename="hand_model/object_files/finger_prox.obj"/>
      </geometry>
      <material name="hand_grey"/>
      <origin xyz="0.0 0.0 0.0" rpy="-1.5707963267948966 0.0 0.0"/>
    </visual>
    <collision>
      <geometry>
        <mesh filename="hand_model/object_files/finger_prox.obj"/>
      </geometry>
      <origin xyz="0.0 0.0 0.0" rpy="-1.5707963267948966 0.0 0.0"/>
    </collision>
  </link>
  <link name="f1_middle_link">
    <inertial>
      <origin xyz="0.0 0.0 0.0" rpy="0.0 -0.0 0.0"/>
      <mass value="0.075"/>
      <inertia ixx="0.0" ixy="0.0" ixz="0.0" iyy="0.0" iyz="0.0" izz="0.0"/>
    </inertial>
    <visual>
      <geometry>
        <mesh filename="hand_model/object_files/finger_med.obj"/>
      </geometry>
      <material name="hand_grey"/>
      <origin xyz="0.0 0.0 0.0" rpy="-1.5707963267948966 0.0 0.0"/>
    </visual>
    <collision>
      <geometry>
        <mesh filename="hand_model/object_files/finger_med.obj"/>
      </geometry>
      <origin xyz="0.0 0.0 0.0" rpy="-1.5707963267948966 0.0 0.0"/>
    </collision>
  </link>
  <link name="f1_distal_link">
    <inertial>
      <origin xyz="0.0 0.0 0.0" rpy="0.0 -0.0 0.0"/>
      <mass value="0.025"/>
      <inertia ixx="0.0" ixy="0.0" ixz="0.0" iyy="0.0" iyz="0.0" izz="0.0"/>
    </inertial>
    <visual>
      <geometry>
        <mesh filename="hand_model/object_files/finger_dist_pill.obj" scale="0.001 0.001 0.001"/>
      </geometry>
      <material name="hand_grey"/>
      <origin xyz="0.0 0.0 0.0" rpy="-1.5707963267948966 0.0 0.0"/>
    </visual>
    <collision>
       <geometry>
        <mesh filename="tips/tips_simple_subd2_cy.obj" scale="0.001 0.001 0.001"/>
      </geometry>
       <origin xyz="0.0 0.0 0.0" rpy="-1.5707963267948966 0.0 0.0"/>
    </collision>
    <collision>
       <geometry>
        <mesh filename="tips/tips_simple_subd2_sp.obj" scale="0.001 0.001 0.001"/>
      </geometry>
       <origin xyz="0.0 0.0 0.0" rpy="-1.5707963267948966 0.0 0.0"/>
    </collision>
  </link>
  <link name="f2_base_link">
    <inertial>
      <origin xyz="0.0 0.0 0.0" rpy="0.0 -0.0 0.0"/>
      <mass value="0.1"/>
      <inertia ixx="0.0" ixy="0.0" ixz="0.0" iyy="0.0" iyz="0.0" izz="0.0"/>
    </inertial>
  </link>
  <link name="f2_proximal_link">
    <inertial>
      <origin xyz="0.0 0.0 0.0" rpy="0.0 -0.0 0.0"/>
      <mass value="0.0"/>
      <inertia ixx="0.0" ixy="0.0" ixz="0.0" iyy="0.0" iyz="0.0" izz="0.0"/>
    </inertial>
  </link>
  <link name="f2_knuckle_link">
    <inertial>
      <origin xyz="0.0 0.0 0.0" rpy="0.0 -0.0 0.0"/>
      <mass value="0.1"/>
      <inertia ixx="0.0" ixy="0.0" ixz="0.0" iyy="0.0" iyz="0.0" izz="0.0"/>
    </inertial>
    <visual>
      <geometry>
        <mesh filename="hand_model/object_files/finger_prox.obj"/>
      </geometry>
      <material name="hand_grey"/>
      <origin xyz="0.0 0.0 0.0" rpy="-1.5707963267948966 0.0 0.0"/>
    </visual>
    <collision>
      <geometry>
        <mesh filename="hand_model/object_files/finger_prox.obj"/>
      </geometry>
      <origin xyz="0.0 0.0 0.0" rpy="-1.5707963267948966 0.0 0.0"/>
    </collision>
  </link>
  <link name="f2_middle_link">
    <inertial>
      <origin xyz="0.0 0.0 0.0" rpy="0.0 -0.0 0.0"/>
      <mass value="0.075"/>
      <inertia ixx="0.0" ixy="0.0" ixz="0.0" iyy="0.0" iyz="0.0" izz="0.0"/>
    </inertial>
    <visual>
      <geometry>
        <mesh filename="hand_model/object_files/finger_med.obj"/>
      </geometry>
      <material name="hand_grey"/>
      <origin xyz="0.0 0.0 0.0" rpy="-1.5707963267948966 0.0 0.0"/>
    </visual>
    <collision>
      <geometry>
        <mesh filename="hand_model/object_files/finger_med.obj"/>
      </geometry>
      <origin xyz="0.0 0.0 0.0" rpy="-1.5707963267948966 0.0 0.0"/>
    </collision>
  </link>
  <link name="f2_distal_link">
    <inertial>
      <origin xyz="0.0 0.0 0.0" rpy="0.0 -0.0 0.0"/>
      <mass value="0.025"/>
      <inertia ixx="0.0" ixy="0.0" ixz="0.0" iyy="0.0" iyz="0.0" izz="0.0"/>
    </inertial>
    <visual>
      <geometry>
        <mesh filename="hand_model/object_files/finger_dist_pill.obj" scale="0.001 0.001 0.001"/>
      </geometry>
      <material name="hand_grey"/>
      <origin xyz="0.0 0.0 0.0" rpy="-1.5707963267948966 0.0 0.0"/>
    </visual>
    <collision>
       <geometry>
        <mesh filename="tips/tips_simple_subd2_cy.obj" scale="0.001 0.001 0.001"/>
      </geometry>
       <origin xyz="0.0 0.0 0.0" rpy="-1.5707963267948966 0.0 0.0"/>
    </collision>
    <collision>
       <geometry>
        <mesh filename="tips/tips_simple_subd2_sp.obj" scale="0.001 0.001 0.001"/>
      </geometry>
       <origin xyz="0.0 0.0 0.0" rpy="-1.5707963267948966 0.0 0.0"/>
    </collision>
  </link>
  <link name="f3_base_link">
    <inertial>
      <origin xyz="0.0 0.0 0.0" rpy="0.0 -0.0 0.0"/>
      <mass value="0.1"/>
      <inertia ixx="0.0" ixy="0.0" ixz="0.0" iyy="0.0" iyz="0.0" izz="0.0"/>
    </inertial>
  </link>
  <link name="f3_proximal_link">
    <inertial>
      <origin xyz="0.0 0.0 0.0" rpy="0.0 -0.0 0.0"/>
      <mass value="0.0"/>
      <inertia ixx="0.0" ixy="0.0" ixz="0.0" iyy="0.0" iyz="0.0" izz="0.0"/>
    </inertial>
  </link>
  <link name="f3_knuckle_link">
    <inertial>
      <origin xyz="0.0 0.0 0.0" rpy="0.0 -0.0 0.0"/>
      <mass value="0.1"/>
      <inertia ixx="0.0" ixy="0.0" ixz="0.0" iyy="0.0" iyz="0.0" izz="0.0"/>
    </inertial>
    <visual>
      <geometry>
        <mesh filename="hand_model/object_files/finger_prox.obj"/>
      </geometry>
      <material name="hand_grey"/>
      <origin xyz="0.0 0.0 0.0" rpy="-1.5707963267948966 0.0 0.0"/>
    </visual>
    <collision>
      <geometry>
        <mesh filename="hand_model/object_files/finger_prox.obj"/>
      </geometry>
      <origin xyz="0.0 0.0 0.0" rpy="-1.5707963267948966 0.0 0.0"/>
    </collision>
  </link>
  <link name="f3_middle_link">
    <inertial>
      <origin xyz="0.0 0.0 0.0" rpy="0.0 -0.0 0.0"/>
      <mass value="0.075"/>
      <inertia ixx="0.0" ixy="0.0" ixz="0.0" iyy="0.0" iyz="0.0" izz="0.0"/>
    </inertial>
    <visual>
      <geometry>
        <mesh filename="hand_model/object_files/finger_med.obj"/>
      </geometry>
      <material name="hand_grey"/>
      <origin xyz="0.0 0.0 0.0" rpy="-1.5707963267948966 0.0 0.0"/>
    </visual>
    <collision>
      <geometry>
        <mesh filename="hand_model/object_files/finger_med.obj"/>
      </geometry>
      <origin xyz="0.0 0.0 0.0" rpy="-1.5707963267948966 0.0 0.0"/>
    </collision>
  </link>
  <link name="f3_distal_link">
    <inertial>
      <origin xyz="0.0 0.0 0.0" rpy="0.0 -0.0 0.0"/>
      <mass value="0.025"/>
      <inertia ixx="0.0" ixy="0.0" ixz="0.0" iyy="0.0" iyz="0.0" izz="0.0"/>
    </inertial>
    <visual>
      <geometry>
        <mesh filename="hand_model/object_files/finger_dist_pill.obj" scale="0.001 0.001 0.001"/>
      </geometry>
      <material name="hand_grey"/>
      <origin xyz="0.0 0.0 0.0" rpy="-1.5707963267948966 0.0 0.0"/>
    </visual>
    <collision>
       <geometry>
        <mesh filename="tips/tips_simple_subd2_cy.obj" scale="0.001 0.001 0.001"/>
      </geometry>
       <origin xyz="0.0 0.0 0.0" rpy="-1.5707963267948966 0.0 0.0"/>
    </collision>
    <collision>
       <geometry>
        <mesh filename="tips/tips_simple_subd2_sp.obj" scale="0.001 0.001 0.001"/>
      </geometry>
       <origin xyz="0.0 0.0 0.0" rpy="-1.5707963267948966 0.0 0.0"/>
    </collision>
  </link>
  <link name="f4_base_link">
    <inertial>
      <origin xyz="0.0 0.0 0.0" rpy="0.0 -0.0 0.0"/>
      <mass value="0.1"/>
      <inertia ixx="0.0" ixy="0.0" ixz="0.0" iyy="0.0" iyz="0.0" izz="0.0"/>
    </inertial>
  </link>
  <link name="f4_proximal_link">
    <inertial>
      <origin xyz="0.0 0.0 0.0" rpy="0.0 -0.0 0.0"/>
      <mass value="0.0"/>
      <inertia ixx="0.0" ixy="0.0" ixz="0.0" iyy="0.0" iyz="0.0" izz="0.0"/>
    </inertial>
  </link>
  <link name="f4_knuckle_link">
    <inertial>
      <origin xyz="0.0 0.0 0.0" rpy="0.0 -0.0 0.0"/>
      <mass value="0.1"/>
      <inertia ixx="0.0" ixy="0.0" ixz="0.0" iyy="0.0" iyz="0.0" izz="0.0"/>
    </inertial>
    <visual>
      <geometry>
        <mesh filename="hand_model/object_files/finger_prox.obj"/>
      </geometry>
      <material name="hand_grey"/>
      <origin xyz="0.0 0.0 0.0" rpy="-1.5707963267948966 0.0 0.0"/>
    </visual>
    <collision>
      <geometry>
        <mesh filename="hand_model/object_files/finger_prox.obj"/>
      </geometry>
      <origin xyz="0.0 0.0 0.0" rpy="-1.5707963267948966 0.0 0.0"/>
    </collision>
  </link>
  <link name="f4_middle_link">
    <inertial>
      <origin xyz="0.0 0.0 0.0" rpy="0.0 -0.0 0.0"/>
      <mass value="0.075"/>
      <inertia ixx="0.0" ixy="0.0" ixz="0.0" iyy="0.0" iyz="0.0" izz="0.0"/>
    </inertial>
    <visual>
      <geometry>
        <mesh filename="hand_model/object_files/finger_med.obj"/>
      </geometry>
      <material name="hand_grey"/>
      <origin xyz="0.0 0.0 0.0" rpy="-1.5707963267948966 0.0 0.0"/>
    </visual>
    <collision>
      <geometry>
        <mesh filename="hand_model/object_files/finger_med.obj"/>
      </geometry>
      <origin xyz="0.0 0.0 0.0" rpy="-1.5707963267948966 0.0 0.0"/>
    </collision>
  </link>
  <link name="f4_distal_link">
    <inertial>
      <origin xyz="0.0 0.0 0.0" rpy="0.0 -0.0 0.0"/>
      <mass value="0.025"/>
      <inertia ixx="0.0" ixy="0.0" ixz="0.0" iyy="0.0" iyz="0.0" izz="0.0"/>
    </inertial>
    <visual>
      <geometry>
        <mesh filename="hand_model/object_files/finger_dist_pill.obj" scale="0.001 0.001 0.001"/>
      </geometry>
      <material name="hand_grey"/>
      <origin xyz="0.0 0.0 0.0" rpy="-1.5707963267948966 0.0 0.0"/>
    </visual>
    <collision>
       <geometry>
        <mesh filename="tips/tips_simple_subd2_cy.obj" scale="0.001 0.001 0.001"/>
      </geometry>
       <origin xyz="0.0 0.0 0.0" rpy="-1.5707963267948966 0.0 0.0"/>
    </collision>
    <collision>
       <geometry>
        <mesh filename="tips/tips_simple_subd2_sp.obj" scale="0.001 0.001 0.001"/>
      </geometry>
       <origin xyz="0.0 0.0 0.0" rpy="-1.5707963267948966 0.0 0.0"/>
    </collision>
  </link>
  <joint name="f1_base_transformation_fixed" type="fixed">
    <parent link="hand_base"/>
    <child link="f1_base_link"/>
    <axis xyz="1. 0. 0."/>
    <origin xyz="-0.005785206 -0.061149354 0.132621405" rpy="0.14464487481415556 -1.485459239924849 -2.446541906979036"/>
  </joint>
  <joint name="f1_proximal_joint" type="revolute">
    <limit effort="1000.0" velocity="1000.0" lower="-0.5" upper="0.5"/>
    <parent link="f1_base_link"/>
    <child link="f1_proximal_link"/>
    <axis xyz="0. 0. 1."/>
    <origin xyz="0.0 -0.0 0.0" rpy="0.0 -0.0 0.0"/>
  </joint>
  <joint name="f1_knuckle_joint" type="revolute">
    <limit effort="1000.0" velocity="1000.0" lower="-0.34" upper="1.5"/>
    <parent link="f1_proximal_link"/>
    <child link="f1_knuckle_link"/>
    <axis xyz="0. 0. 1."/>
    <origin xyz="0.0 -0.0 0.0" rpy="1.5707963267948966 -0.0 0.0"/>
  </joint>
  <joint name="f1_middle_joint" type="revolute">
    <limit effort="1000.0" velocity="1000.0" lower="-0.13" upper="1.7"/>
    <parent link="f1_knuckle_link"/>
    <child link="f1_middle_link"/>
    <axis xyz="0. 0. 1."/>
    <origin xyz="0.075 -0.0 0.0" rpy="0.0 -0.0 0.0"/>
  </joint>
  <joint name="f1_distal_joint_passive" type="revolute">
    <limit effort="1000.0" velocity="1000.0" lower="-0.13" upper="1.7"/>
    <parent link="f1_middle_link"/>
    <child link="f1_distal_link"/>
    <axis xyz="0. 0. 1."/>
    <origin xyz="0.04 -0.0 0.0" rpy="0.0 0.0 -1.5707963267948966"/>
  </joint>
  <joint name="f2_base_transformation_fixed" type="fixed">
    <parent link="hand_base"/>
    <child link="f2_base_link"/>
    <axis xyz="1. 0. 0."/>
    <origin xyz="-0.048151365 -0.012101809 0.133300263" rpy="-0.38464095936834725 -1.337289794013638 -2.708519622653562"/>
  </joint>
  <joint name="f2_proximal_joint" type="revolute">
    <limit effort="1000.0" velocity="1000.0" lower="-0.5" upper="0.5"/>
    <parent link="f2_base_link"/>
    <child link="f2_proximal_link"/>
    <axis xyz="0. 0. 1."/>
    <origin xyz="0.0 -0.0 0.0" rpy="0.0 -0.0 0.0"/>
  </joint>
  <joint name="f2_knuckle_joint" type="revolute">
    <limit effort="1000.0" velocity="1000.0" lower="-0.34" upper="1.5"/>
    <parent link="f2_proximal_link"/>
    <child link="f2_knuckle_link"/>
    <axis xyz="0. 0. 1."/>
    <origin xyz="0.0 -0.0 0.0" rpy="1.5707963267948966 -0.0 0.0"/>
  </joint>
  <joint name="f2_middle_joint" type="revolute">
    <limit effort="1000.0" velocity="1000.0" lower="-0.13" upper="1.7"/>
    <parent link="f2_knuckle_link"/>
    <child link="f2_middle_link"/>
    <axis xyz="0. 0. 1."/>
    <origin xyz="0.075 -0.0 0.0" rpy="0.0 -0.0 0.0"/>
  </joint>
  <joint name="f2_distal_joint_passive" type="revolute">
    <limit effort="1000.0" velocity="1000.0" lower="-0.13" upper="1.7"/>
    <parent link="f2_middle_link"/>
    <child link="f2_distal_link"/>
    <axis xyz="0. 0. 1."/>
    <origin xyz="0.04 -0.0 0.0" rpy="0.0 0.0 -1.5707963267948966"/>
  </joint>
  <joint name="f3_base_transformation_fixed" type="fixed">
    <parent link="hand_base"/>
    <child link="f3_base_link"/>
    <axis xyz="1. 0. 0."/>
    <origin xyz="-0.045982316 0.027691585 0.138843566" rpy="-0.38464095936834725 -1.337289794013638 -2.708519622653562"/>
  </joint>
  <joint name="f3_proximal_joint" type="revolute">
    <limit effort="1000.0" velocity="1000.0" lower="-0.5" upper="0.5"/>
    <parent link="f3_base_link"/>
    <child link="f3_proximal_link"/>
    <axis xyz="0. 0. 1."/>
    <origin xyz="0.0 -0.0 0.0" rpy="0.0 -0.0 0.0"/>
  </joint>
  <joint name="f3_knuckle_joint" type="revolute">
    <limit effort="1000.0" velocity="1000.0" lower="-0.34" upper="1.5"/>
    <parent link="f3_proximal_link"/>
    <child link="f3_knuckle_link"/>
    <axis xyz="0. 0. 1."/>
    <origin xyz="0.0 -0.0 0.0" rpy="1.5707963267948966 -0.0 0.0"/>
  </joint>
  <joint name="f3_middle_joint" type="revolute">
    <limit effort="1000.0" velocity="1000.0" lower="-0.13" upper="1.7"/>
    <parent link="f3_knuckle_link"/>
    <child link="f3_middle_link"/>
    <axis xyz="0. 0. 1."/>
    <origin xyz="0.075 -0.0 0.0" rpy="0.0 -0.0 0.0"/>
  </joint>
  <joint name="f3_distal_joint_passive" type="revolute">
    <limit effort="1000.0" velocity="1000.0" lower="-0.13" upper="1.7"/>
    <parent link="f3_middle_link"/>
    <child link="f3_distal_link"/>
    <axis xyz="0. 0. 1."/>
    <origin xyz="0.04 -0.0 0.0" rpy="0.0 0.0 -1.5707963267948966"/>
  </joint>
  <joint name="f4_base_transformation_fixed" type="fixed">
    <parent link="hand_base"/>
    <child link="f4_base_link"/>
    <axis xyz="1. 0. 0."/>
    <origin xyz="0.052264236 0.026986124 0.102620128" rpy="0.547040025261126 -0.9823732784666147 -0.578402029433078"/>
  </joint>
  <joint name="f4_proximal_joint" type="revolute">
    <limit effort="1000.0" velocity="1000.0" lower="-0.5" upper="0.5"/>
    <parent link="f4_base_link"/>
    <child link="f4_proximal_link"/>
    <axis xyz="0. 0. 1."/>
    <origin xyz="0.0 -0.0 0.0" rpy="0.0 -0.0 0.0"/>
  </joint>
  <joint name="f4_knuckle_joint" type="revolute">
    <limit effort="1000.0" velocity="1000.0" lower="-0.34" upper="1.5"/>
    <parent link="f4_proximal_link"/>
    <child link="f4_knuckle_link"/>
    <axis xyz="0. 0. 1."/>
    <origin xyz="0.0 -0.0 0.0" rpy="1.5707963267948966 -0.0 0.0"/>
  </joint>
  <joint name="f4_middle_joint" type="revolute">
    <limit effort="1000.0" velocity="1000.0" lower="-0.13" upper="1.7"/>
    <parent link="f4_knuckle_link"/>
    <child link="f4_middle_link"/>
    <axis xyz="0. 0. 1."/>
    <origin xyz="0.075 -0.0 0.0" rpy="0.0 -0.0 0.0"/>
  </joint>
  <joint name="f4_distal_joint_passive" type="revolute">
    <limit effort="1000.0" velocity="1000.0" lower="-0.13" upper="1.7"/>
    <parent link="f4_middle_link"/>
    <child link="f4_distal_link"/>
    <axis xyz="0. 0. 1."/>
    <origin xyz="0.04 -0.0 0.0" rpy="0.0 0.0 -1.5707963267948966"/>
  </joint>
  <material name="base_and_dock_material">
    <color rgba="0.  0.  0.5 1. "/>
  </material>
  <material name="hand_red">
    <color rgba="1. 0. 0. 1."/>
  </material>
  <material name="hand_blue">
    <color rgba="0. 0. 1. 1."/>
  </material>
  <material name="hand_green">
    <color rgba="0. 1. 0. 1."/>
  </material>
  <material name="hand_yellow">
    <color rgba="1. 1. 0. 1."/>
  </material>
  <material name="hand_purple">
    <color rgba="1. 0. 1. 1."/>
  </material>
  <material name="hand_grey">
    <color rgba="0.8 0.8 0.8 1. "/>
  </material>
  <material name="hand_turquoise">
    <color rgba="0. 1. 1. 1."/>
  </material>
</robot>
